<?xml version="1.0"?>
<robot name="museum_navigator_robot"
	xmlns:xacro="http://www.ros.org/wiki/xacro">
	<xacro:property name="cameraSize" value="0.05" />
	<xacro:property name="cameraMass" value="0.1" />

	<material name="black">
		<color rgba="0.0 0.0 0.0 1.0"/>
	</material>

	<material name="blue">
		<color rgba="0.0 0.0 0.8 1.0"/>
	</material>

	<material name="green">
		<color rgba="0.0 0.8 0.0 1.0"/>
	</material>

	<material name="grey">
		<color rgba="0.2 0.2 0.2 1.0"/>
	</material>

	<material name="orange">
		<color rgba="${255/255} ${108/255} ${10/255} 1.0"/>
	</material>

	<material name="brown">
		<color rgba="${222/255} ${207/255} ${195/255} 1.0"/>
	</material>

	<material name="red">
		<color rgba="0.8 0.0 0.0 1.0"/>
	</material>

	<material name="white">
		<color rgba="1.0 1.0 1.0 1.0"/>
	</material>
	<!-- <include filename="museum_nav.gazebo.xacro" /> -->
	<gazebo>
		<plugin filename="libgazebo_ros_joint_state_publisher.so" name="joint_state_publisher">
			<jointName>left_wheel_hinge, right_wheel_hinge</jointName>
			<updateRate>10.0</updateRate>
			<alwaysOn>true</alwaysOn>
		</plugin>
		<plugin name="differential_drive_controller" filename="libgazebo_ros_diff_drive.so">
			<legacyMode>false</legacyMode>
			<alwaysOn>true</alwaysOn>
			<updateRate>10</updateRate>
			<leftJoint>left_wheel_hinge</leftJoint>
			<rightJoint>right_wheel_hinge</rightJoint>
			<wheelSeparation>0.4</wheelSeparation>
			<wheelDiameter>0.2</wheelDiameter>
			<torque>10</torque>
			<commandTopic>cmd_vel</commandTopic>
			<odometryTopic>odom</odometryTopic>
			<odometryFrame>odom</odometryFrame>
			<robotBaseFrame>chassis</robotBaseFrame>
		</plugin>
	</gazebo>
	<gazebo reference="chassis">
		<material name="orange"/>
	</gazebo>
	<gazebo reference="front_caster">
		<mu1>0.0</mu1>
		<mu2>0.0</mu2>
		<material name="grey"/>
	</gazebo>
	<gazebo reference="back_caster">
		<mu1>0.0</mu1>
		<mu2>0.0</mu2>
		<material name="grey"/>
	</gazebo>
	<gazebo reference="left_wheel">
		<material name="black"/>
	</gazebo>
	<gazebo reference="right_wheel">
		<material name="black"/>
	</gazebo>
	<gazebo reference="camera">
		<material name="black"/>
		<sensor type="camera" name="camera1">
			<update_rate>30.0</update_rate>
			<alwaysOn>	true  </alwaysOn>
			<camera name="head_cam">
				<horizontal_fov>	1.62634  </horizontal_fov>
				<image>
					<width>1024</width>
					<height>720</height>
					<format>R8G8B8</format>
				</image>
				<clip>
					<near>0.02</near>
					<far>300</far>
				</clip>
			</camera>
			<plugin name="camera_controller" filename="libgazebo_ros_camera.so">
				<cameraName>	museum_nav/camera1  </cameraName>
				<imageTopicName>	image_raw  </imageTopicName>
				<cameraInfoTopicName>	camera_info  </cameraInfoTopicName>
				<frameName>	camera  </frameName>
				<hackBaseline>	0.07  </hackBaseline>
				<distortionK1>	0.0  </distortionK1>
				<distortionK2>	0.0  </distortionK2>
				<distortionK3>	0.0  </distortionK3>
				<distortionT1>	0.0  </distortionT1>
				<distortionT2>	0.0  </distortionT2>
			</plugin>
		</sensor>
	</gazebo>	<!-- hokuyo -->
	<gazebo reference="hokuyo">
		<sensor type="gpu_ray" name="head_hokuyo_sensor">
			<pose>0 0 0 0 0 0</pose>
			<visualize>true</visualize>
			<update_rate>40</update_rate>
			<ray>
				<scan>
					<horizontal>
						<samples>360</samples>
						<resolution>1</resolution>
						<min_angle>-3.14159</min_angle>
						<max_angle>3.14159</max_angle>
					</horizontal>
				</scan>
				<range>
					<min>		0.25</min>
					<max>		30.0</max>
					<resolution>		0.01</resolution>
				</range>
				<noise>
					<type>		gaussian</type>					<!--
	Noise parameters based on published spec for Hokuyo laser
	achieving "+-30mm" accuracy at range < 10m.  A mean of 0.0m and
	stddev of 0.01m will put 99.7% of samples within 0.03m of the true
	reading.
	-->
					<mean>		0.0</mean>
					<stddev>		0.001</stddev>
				</noise>
			</ray>
			<plugin name="gazebo_ros_head_hokuyo_controller" filename="libgazebo_ros_gpu_laser.so">
				<topicName>	/museum_nav/laser/scan  </topicName>
				<frameName>	hokuyo  </frameName>
			</plugin>
		</sensor>
	</gazebo>
	<gazebo reference="imu_sensor">
		<material name="green"/>
		<gravity>true</gravity>
		<sensor name="imu_sensor" type="imu">
			<always_on>1</always_on>
			<update_rate>1000</update_rate>
			<visualize>1</visualize>
			<topic>__default_topic__</topic>
			<plugin name="imu_plugin" filename="libgazebo_ros_imu_sensor.so">
				<topicName>	imu_data  </topicName>
				<frameName>	imu_sensor  </frameName>
				<bodyName>	imu_sensor  </bodyName>
				<updateRateHZ>	100.0  </updateRateHZ>
				<gaussianNoise>	0.0  </gaussianNoise>
				<xyzOffset>	0 0 0  </xyzOffset>
				<rpyOffset>	0 0 0  </rpyOffset>
			</plugin>
			<pose>0 0 0 0 0 0</pose>
		</sensor>
	</gazebo>
	<gazebo reference="gps">
		<material name="green"/>
		<gravity>true</gravity>
		<sensor name="gps" type="gps">
			<always_on>1</always_on>
			<update_rate>5</update_rate>
			<visualize>1</visualize>
			<topic>__default_topic__</topic>
			<plugin filename="libhector_gazebo_ros_gps.so" name="novatel_gps_sim">
				<bodyName>gps</bodyName>
				<topicName>fix</topicName>
				<velocityTopicName>fix_velocity</velocityTopicName>
				<frameId>gps</frameId>
				<drift>0.0 0.0 0.0</drift>
				<gaussianNoise>0.001 0.001 0.001</gaussianNoise>
				<velocityDrift>0 0 0</velocityDrift>
				<velocityGaussianNoise>0.001 0.001 0.001</velocityGaussianNoise>
				<referenceLatitude>0.0</referenceLatitude>
				<referenceLongitude>0.0</referenceLongitude>
				<referenceHeading>0</referenceHeading>
			</plugin>
			<pose>0 0 0 0 0 0</pose>
		</sensor>
	</gazebo>
	<link name="chassis">
		<pose>
			0 0 0.1 0 0 0
		</pose>
		<!-- <inertial>
			<mass value="5.0" />
			<origin xyz="0.0 0 0" rpy=" 0 0 0" />
			<inertia ixx="0.1" ixy="0" ixz="0" iyy="0.1" iyz="0" izz="0.1" />
		</inertial> -->
		<collision name="collision">
			<origin xyz="0 0 0" rpy=" 0 0 0" />
			<geometry>
				<box size=".28 .28 .1" />
			</geometry>
		</collision>
		<visual name="chassis_visual">
			<origin xyz="0 0 0.7" rpy=" 0 0 0" />
			<geometry>
				<cylinder radius="0.18" length="1.4" />
			</geometry>
		</visual>
		<collision name="bothead">
			<origin xyz="0 0 1.4" rpy=" 0 0 0" />
			<geometry>
				<sphere radius="0.18" />
			</geometry>
		</collision>
		<visual name="bothead_visual">
			<origin xyz="0 0 1.4" rpy=" 0 0 0" />
			<geometry>
				<sphere radius="0.18" />
			</geometry>
		</visual>
	</link>
	<joint name="back_caster_joint" type="fixed">
		<parent link="chassis" />
		<child link="back_caster" />
		<origin xyz="-0.14 0 -0.05" rpy="0.0 0.0 0.0" />
	</joint>
	<link name="back_caster">
		<inertial>
			<mass value="0.5" />
			<origin xyz="0.0 0 0" rpy=" 0 0 0" />
			<inertia ixx="0.1" ixy="0" ixz="0" iyy="0.1" iyz="0" izz="0.1" />
		</inertial>
		<collision name="back_caster_collision">
			<origin xyz="0 0 0" rpy="0 0 0" />
			<geometry>
				<sphere radius="0.05" />
			</geometry>
		</collision>
		<visual name="back_caster_visual">
			<origin xyz="0 0 0" rpy=" 0 0 0" />
			<geometry>
				<sphere radius="0.05" />
			</geometry>
		</visual>
	</link>
	<joint name="front_caster_joint" type="fixed">
		<parent link="chassis" />
		<child link="front_caster" />
		<origin xyz="0.14 0 -0.05" rpy="0.0 0.0 0.0" />
	</joint>
	<link name="front_caster">
		<inertial>
			<mass value="0.5" />
			<origin xyz="0.0 0 0" rpy=" 0 0 0" />
			<inertia ixx="0.1" ixy="0" ixz="0" iyy="0.1" iyz="0" izz="0.1" />
		</inertial>
		<collision name="front_caster_collision">
			<origin xyz="0 0 0" rpy="0 0 0" />
			<geometry>
				<sphere radius="0.05" />
			</geometry>
		</collision>
		<visual name="front_caster_visual">
			<origin xyz="0 0 0" rpy="0 0 0" />
			<geometry>
				<sphere radius="0.05" />
			</geometry>
		</visual>
	</link>
	<joint type="continuous" name="left_wheel_hinge">
		<origin xyz="0 .23 0" rpy="0 0 0" />
		<child link="left_wheel" />
		<parent link="chassis" />
		<axis xyz="0 1 0" rpy="0 0 0" />
		<limit effort="10000" velocity="1000" />
		<dynamics damping="1.0" friction="1.0" />
	</joint>
	<transmission name="left_wheel_hinge_trans" type="SimpleTransmission">
		<type>
			transmission_interface/SimpleTransmission
		</type>
		<actuator name="left_wheel_hinge_motor">
			<mechanicalReduction>
				1
			</mechanicalReduction>
		</actuator>
		<joint name="left_wheel_hinge">
			<hardwareInterface>
				hardware_interface/VelocityJointInterface
			</hardwareInterface>
		</joint>
	</transmission>
	<link name="left_wheel">
		<inertial>
			<origin xyz="0.0 0.0 0.0" rpy="1.57079632679 0.0 0" />
			<mass value="0.8" />
			<inertia ixx="0.1" ixy="0.0" ixz="0.0" iyy="0.1" iyz="0.0" izz="0.1" />
		</inertial>
		<visual name="left_wheel_visual">
			<origin xyz="0.0 0.0 0.0" rpy="1.57079632679 0.0 0" />
			<geometry>
				<cylinder radius="0.1" length="0.05" />
			</geometry>
		</visual>
		<collision name="left_wheel_collision">
			<origin xyz="0.0 0.0 0.0" rpy="1.57079632679 0.0 0" />
			<geometry>
				<cylinder radius="0.1" length="0.05" />
			</geometry>
		</collision>
	</link>
	<joint type="continuous" name="right_wheel_hinge">
		<origin xyz="0 -.23 0" rpy="0 0 0" />
		<child link="right_wheel" />
		<parent link="chassis" />
		<axis xyz="0 1 0" rpy="0 0 0" />
		<limit effort="10000" velocity="1000" />
		<dynamics damping="1.0" friction="1.0" />
	</joint>
	<transmission name="right_wheel_hinge_trans" type="SimpleTransmission">
		<type>
			transmission_interface/SimpleTransmission
		</type>
		<actuator name="right_wheel_hinge_motor">
			<mechanicalReduction>
				1
			</mechanicalReduction>
		</actuator>
		<joint name="right_wheel_hinge">
			<hardwareInterface>
				hardware_interface/VelocityJointInterface
			</hardwareInterface>
		</joint>
	</transmission>
	<link name="right_wheel">
		<inertial>
			<origin xyz="0.0 0.0 0.0" rpy="1.57079632679 0.0 0" />
			<mass value="0.8" />
			<inertia ixx="0.1" ixy="0.0" ixz="0.0" iyy="0.1" iyz="0.0" izz="0.1" />
		</inertial>
		<visual name="right_wheel_visual">
			<origin xyz="0.0 0.0 0.0" rpy="1.57079632679 0.0 0" />
			<geometry>
				<cylinder radius="0.1" length="0.05" />
			</geometry>
		</visual>
		<collision name="right_wheel_collision">
			<origin xyz="0.0 0.0 0.0" rpy="1.57079632679 0.0 0" />
			<geometry>
				<cylinder radius="0.1" length="0.05" />
			</geometry>
		</collision>
	</link>
	<joint name="camera_joint" type="fixed">
		<parent link="chassis" />
		<child link="camera" />
		<origin xyz="0.18 0.0 1.3" rpy="0.0 0.0 0.0" />
	</joint>
	<link name="camera">
		<inertial>
			<origin xyz="0.0 0.0 0.0" rpy="0.0 0.0 0.0" />
			<mass value="${cameraMass}" />
			<box_inertia m="${cameraMass}" x="${cameraSize}" y="${cameraSize}" z="${cameraSize}" />
			<inertia ixx="1e-6" ixy="0" ixz="0" iyy="1e-6" iyz="0" izz="1e-6" />
		</inertial>
		<visual name="camera_visual">
			<origin xyz="0.0 0.0 0.0" rpy="0.0 0.0 0.0" />
			<geometry>
				<box size="${cameraSize} ${cameraSize} ${cameraSize}" />
			</geometry>
		</visual>
		<collision name="camera_collision">
			<origin xyz="0.0 0.0 0.0" rpy="0.0 0.0 0.0" />
			<geometry>
				<box size="${cameraSize} ${cameraSize} ${cameraSize}" />
			</geometry>
		</collision>
	</link>
	<joint name="hokuyo_joint" type="fixed">
		<parent link="chassis" />
		<child link="hokuyo" />
		<origin xyz="0.0 0.0 0.15" rpy="0.0 0.0 0.0" />
	</joint>
	<link name="hokuyo">
		<inertial>
			<origin xyz="0.0 0.0 0.0" rpy="0.0 0.0 0.0" />
			<mass value="1e-5" />
			<inertia ixx="1e-6" ixy="0.0" ixz="0.0" iyy="1e-6" iyz="0.0" izz="1e-6" />
		</inertial>
		<visual name="hokuyo_visual">
			<origin xyz="0.0 0.0 0.0" rpy="0.0 0.0 0.0" />
			<geometry>
				<mesh filename="package://diff_drive_bot/meshes/hokuyo.dae" />
			</geometry>
		</visual>
		<collision name="hokuyo_collision">
			<origin xyz="0.0 0.0 0.0" rpy="0.0 0.0 0.0" />
			<geometry>
				<box size="0.05 0.05 0.05" />
			</geometry>
		</collision>
	</link>
	<joint name="imu_joint" type="fixed">
		<axis xyz="0 0 1" />
		<origin xyz="0 0 0" rpy="0 0 0" />
		<parent link="chassis" />
		<child link="imu_sensor" />
	</joint>
	<link name="imu_sensor">
		<collision>
			<origin xyz="0 0 0" rpy="0 0 0" />
			<geometry>
				<box size="0.02 0.02 0.02" />
			</geometry>
		</collision>
		<visual>
			<origin xyz="0 0 0" rpy="0 0 0" />
			<geometry>
				<box size="0.02 0.02 0.02" />
			</geometry>
		</visual>
		<inertial>
			<mass value="0.001" />
			<origin xyz="0 0 0" rpy="0 0 0" />
			<inertia ixx="0.00000015" ixy="0" ixz="0" iyy="0.00000015" iyz="0" izz="0.00000015" />
		</inertial>
	</link>
	<joint name="gps_joint" type="fixed">
		<axis xyz="0 0 1" />
		<origin xyz="0 0 0" rpy="0 0 0" />
		<parent link="chassis" />
		<child link="gps" />
	</joint>
	<link name="gps">
		<collision>
			<origin xyz="0 0 0" rpy="0 0 0" />
			<geometry>
				<box size="0.02 0.02 0.02" />
			</geometry>
		</collision>
		<visual>
			<origin xyz="0 0 0" rpy="0 0 0" />
			<geometry>
				<box size="0.02 0.02 0.02" />
			</geometry>
		</visual>
		<inertial>
			<mass value="0.001" />
			<origin xyz="0 0 0" rpy="0 0 0" />
			<inertia ixx="0.00000015" ixy="0" ixz="0" iyy="0.00000015" iyz="0" izz="0.00000015" />
		</inertial>
	</link>

</robot>
